<?xml version="1.0"?>
<robot name="my_robot">
<!-- Base Link -->
<link name="base_link">
  <visual>
    <geometry>
      <box size="0.4 0.3 0.1"/>
    </geometry>
    <material name="base_color">
      <color rgba="0.8 0.8 0.8 1"/>
    </material>
  </visual>
  <collision>
    <geometry>
      <box size="0.4 0.3 0.1"/>
    </geometry>
  </collision>
  <inertial>
    <mass value="5"/>
    <inertia ixx="0.0833" ixy="0" ixz="0" iyy="0.0833" iyz="0" izz="0.1667"/>
  </inertial>
</link>

<!-- Front Left Wheel -->
<link name="front_left_wheel">
  <visual>
    <origin xyz="0 0 0" rpy="1.57079632679 0 0"/>
    <geometry>
      <cylinder radius="0.1" length="0.05"/>
    </geometry>
    <material name="wheel_color">
      <color rgba="0.2 0.2 0.2 1"/>
    </material>
  </visual>
  <collision>
    <origin xyz="0 0 0" rpy="1.57079632679 0 0"/>
    <geometry>
      <cylinder radius="0.1" length="0.05"/>
    </geometry>
  </collision>
  <inertial>
    <mass value="1.0"/>
    <inertia ixx="0.0015" ixy="0" ixz="0" iyy="0.0015" iyz="0" izz="0.0025"/>
  </inertial>
</link>

<joint name="front_left_wheel_joint" type="continuous"># Ball Handling Robot


  <parent link="base_link"/>
  <child link="front_left_wheel"/>
  <origin xyz="0.15 0.15 0" rpy="0 0 0"/>
  <axis xyz="0 1 0"/>
</joint>

<gazebo reference="front_left_wheel">
  <material>Gazebo/Black</material>
</gazebo>

<!-- Front Right Wheel -->
<link name="front_right_wheel">
  <visual>
    <origin xyz="0 0 0" rpy="1.57079632679 0 0"/>
    <geometry>
      <cylinder radius="0.1" length="0.05"/>
    </geometry>
    <material name="wheel_color">
      <color rgba="0.2 0.2 0.2 1"/>
    </material>
  </visual>
  <collision>
    <origin xyz="0 0 0" rpy="1.57079632679 0 0"/>
    <geometry>
      <cylinder radius="0.1" length="0.05"/>
    </geometry>
  </collision>
  <inertial>
    <mass value="1.0"/>
    <inertia ixx="0.0015" ixy="0" ixz="0" iyy="0.0015" iyz="0" izz="0.0025"/>
  </inertial>
</link>

<joint name="front_right_wheel_joint" type="continuous">
  <parent link="base_link"/>
  <child link="front_right_wheel"/>
  <origin xyz="0.15 -0.15 0" rpy="0 0 0"/>
  <axis xyz="0 1 0"/>
</joint>

<gazebo reference="front_right_wheel">
  <material>Gazebo/Black</material>
</gazebo>

<!-- Rear Left Wheel -->
<link name="rear_left_wheel">
  <visual>
    <origin xyz="0 0 0" rpy="1.57079632679 0 0"/>
    <geometry>
      <cylinder radius="0.1" length="0.05"/>
    </geometry>
    <material name="wheel_color">
      <color rgba="0.2 0.2 0.2 1"/>
    </material>
  </visual>
  <collision>
    <origin xyz="0 0 0" rpy="1.57079632679 0 0"/>
    <geometry>
      <cylinder radius="0.1" length="0.05"/>
    </geometry>
  </collision>
  <inertial>
    <mass value="1.0"/>
    <inertia ixx="0.0015" ixy="0" ixz="0" iyy="0.0015" iyz="0" izz="0.0025"/>
  </inertial>
</link>

<joint name="rear_left_wheel_joint" type="continuous">
  <parent link="base_link"/>
  <child link="rear_left_wheel"/>
  <origin xyz="-0.15 0.15 0" rpy="0 0 0"/>
  <axis xyz="0 1 0"/>
</joint>

<gazebo reference="rear_left_wheel">
  <material>Gazebo/Black</material>
</gazebo>

<!-- Rear Right Wheel -->
<link name="rear_right_wheel">
  <visual>
    <origin xyz="0 0 0" rpy="1.57079632679 0 0"/>
    <geometry>
      <cylinder radius="0.1" length="0.05"/>
    </geometry>
    <material name="wheel_color">
      <color rgba="0.2 0.2 0.2 1"/>
    </material>
  </visual>
  <collision>
    <origin xyz="0 0 0" rpy="1.57079632679 0 0"/>
    <geometry>
      <cylinder radius="0.1" length="0.05"/>
    </geometry>
  </collision>
  <inertial>
    <mass value="1.0"/>
    <inertia ixx="0.0015" ixy="0" ixz="0" iyy="0.0015" iyz="0" izz="0.0025"/>
  </inertial>
</link>

<joint name="rear_right_wheel_joint" type="continuous">
  <parent link="base_link"/>
  <child link="rear_right_wheel"/>
  <origin xyz="-0.15 -0.15 0" rpy="0 0 0"/>
  <axis xyz="0 1 0"/>
</joint>

<gazebo reference="rear_right_wheel">
  <material>Gazebo/Black</material>
</gazebo>

<!-- Gripper Base -->
<link name="gripper_base">
  <visual>
    <geometry>
      <box size="0.1 0.1 0.05"/>
    </geometry>
    <material name="gripper_base_color">
      <color rgba="0 0 1 1"/>
    </material>
  </visual>
  <collision>
    <geometry>
      <box size="0.1 0.1 0.05"/>
    </geometry>
  </collision>
  <inertial>
    <mass value="0.2"/>
    <inertia ixx="0.000167" ixy="0" ixz="0" iyy="0.000167" iyz="0" izz="0.000167"/>
  </inertial>
</link>

<joint name="gripper_base_joint" type="fixed">
  <parent link="base_link"/>
  <child link="gripper_base"/>
  <origin xyz="0.2 0 0.075" rpy="0 0 0"/>
</joint>

<gazebo reference="gripper_base">
  <material>Gazebo/Blue</material>
</gazebo>

<!-- Gripper -->
<link name="gripper">
  <visual>
    <origin xyz="0 0 -0.05" rpy="0 0 0"/>
    <geometry>
      <box size="0.2 0.1 0.1"/>
    </geometry>
    <material name="gripper_color">
      <color rgba="0 0 1 1"/>
    </material>
  </visual>
  <collision>
    <origin xyz="0 0 -0.05" rpy="0 0 0"/>
    <geometry>
      <box size="0.2 0.1 0.1"/>
    </geometry>
  </collision>
  <inertial>
    <origin xyz="0 0 -0.05" rpy="0 0 0"/>
    <mass value="0.5"/>
    <inertia ixx="0.001667" ixy="0" ixz="0" iyy="0.001667" iyz="0" izz="0.000833"/>
  </inertial>
</link>

<joint name="gripper_joint" type="prismatic">
  <parent link="gripper_base"/>
  <child link="gripper"/>
  <origin xyz="0 0 0.025" rpy="0 0 0"/>
  <axis xyz="0 1 0"/>
  <limit lower="-0.05" upper="0.05" effort="20" velocity="0.1"/>
</joint>

<gazebo reference="gripper">
  <material>Gazebo/Blue</material>
</gazebo>

<!-- Gripper Left Finger -->
<link name="gripper_finger_left">
  <visual>
    <origin xyz="0.05 0.025 -0.05" rpy="0 0 0"/>
    <geometry>
      <box size="0.1 0.05 0.1"/>
    </geometry>
    <material name="gripper_finger_color">
      <color rgba="0 0 1 1"/>
    </material>
  </visual>
  <collision>
    <origin xyz="0.05 0.025 -0.05" rpy="0 0 0"/>
    <geometry>
      <box size="0.1 0.05 0.1"/>
    </geometry>
  </collision>
  <inertial>
    <origin xyz="0.05 0.025 -0.05" rpy="0 0 0"/>
    <mass value="0.1"/>
    <inertia ixx="0.000083" ixy="0" ixz="0" iyy="0.000083" iyz="0" izz="0.000083"/>
  </inertial>
</link>

<joint name="gripper_finger_left_joint" type="prismatic">
  <parent link="gripper"/>
  <child link="gripper_finger_left"/>
  <origin xyz="-0.1 0 0" rpy="0 0 0"/>
  <axis xyz="1 0 0"/>
  <limit lower="0" upper="0.1" effort="10" velocity="0.1"/>
</joint>

<gazebo reference="gripper_finger_left">
  <material>Gazebo/Blue</material>
</gazebo>

<!-- Gripper Right Finger -->
<link name="gripper_finger_right">
  <visual>
    <origin xyz="-0.05 -0.025 -0.05" rpy="0 0 0"/>
    <geometry>
      <box size="0.1 0.05 0.1"/>
    </geometry>
    <material name="gripper_finger_color">
      <color rgba="0 0 1 1"/>
    </material>
  </visual>
  <collision>
    <origin xyz="-0.05 -0.025 -0.05" rpy="0 0 0"/>
    <geometry>
      <box size="0.1 0.05 0.1"/>
    </geometry>
  </collision>
  <inertial>
    <origin xyz="-0.05 -0.025 -0.05" rpy="0 0 0"/>
    <mass value="0.1"/>
    <inertia ixx="0.000083" ixy="0" ixz="0" iyy="0.000083" iyz="0" izz="0.000083"/>
  </inertial>
</link>

<joint name="gripper_finger_right_joint" type="prismatic">
  <parent link="gripper"/>
  <child link="gripper_finger_right"/>
  <origin xyz="0.1 0 0" rpy="0 0 0"/>
  <axis xyz="-1 0 0"/>
  <limit lower="-0.1" upper="0" effort="10" velocity="0.1"/>
  <mimic joint="gripper_finger_left_joint" multiplier="-1"/>
</joint>

<gazebo reference="gripper_finger_right">
  <material>Gazebo/Blue</material>
</gazebo>

<!-- Depth Camera -->
<link name="camera_link">
  <visual>
    <geometry>
      <box size="0.05 0.05 0.05"/>
    </geometry>
    <material name="camera_color">
      <color rgba="0.8 0.8 0.8 0.8"/>
    </material>
  </visual>
  <collision>
    <geometry>
      <box size="0.05 0.05 0.05"/>
    </geometry>
  </collision>
  <inertial>
    <mass value="0.1"/>
    <inertia ixx="0.000083" ixy="0" ixz="0" iyy="0.000083" iyz="0" izz="0.000083"/>
  </inertial>
</link>

<joint name="camera_joint" type="fixed">
  <parent link="base_link"/>
  <child link="camera_link"/>
  <origin xyz="0.2 0 0.1" rpy="0 0 0"/>
</joint>

<gazebo reference="camera_link">
  <sensor type="depth" name="depth_camera">
    <update_rate>30</update_rate>
    <camera>
      <horizontal_fov>1.047198</horizontal_fov>
      <image>
        <width>640</width>
        <height>480</height>
        <format>R8G8B8</format>
      </image>
      <clip>
        <near>0.05</near>
        <far>3.0</far>
      </clip>
    </camera>
    <plugin name="camera_plugin" filename="libgazebo_ros_openni_kinect.so">
      <baseline>0.2</baseline>
      <alwaysOn>true</alwaysOn>
      <updateRate>0.0</updateRate>
      <cameraName>camera</cameraName>
      <imageTopicName>/camera/color/image_raw</imageTopicName>
      <cameraInfoTopicName>/camera/color/camera_info</cameraInfoTopicName>
      <depthImageTopicName>/camera/depth/image_raw</depthImageTopicName>
      <depthImageInfoTopicName>/camera/depth/camera_info</depthImageInfoTopicName>
      <pointCloudTopicName>/camera/depth/points</pointCloudTopicName>
      <frameName>camera_link</frameName>
      <pointCloudCutoff>0.5</pointCloudCutoff>
      <pointCloudCutoffMax>3.0</pointCloudCutoffMax>
      <distortionK1>0.00000001</distortionK1>
      <distortionK2>0.00000001</distortionK2>
      <distortionK3>0.00000001</distortionK3>
      <distortionT1>0.00000001</distortionT1>
      <distortionT2>0.00000001</distortionT2>
      <CxPrime>0</CxPrime>
      <Cx>0</Cx>
      <Cy>0</Cy>
      <focalLength>0</focalLength>
      <hackBaseline>0</hackBaseline>
    </plugin>
  </sensor>
  </gazebo>

</robot>
